Workbook

Sheet S-201 list
A1: Generated by formulas from the Source sheet — do not type here. In S-201 AtoN Studio → Excel → S-201, load this workbook and keep the sheet "S-201 list".
A2: AtoN number | B2: Aid type | C2: Name | D2: Latitude | E2: Longitude | F2: Colour | G2: Colour pattern | H2: Shape | I2: Category | J2: Light character | K2: Focal height | L2: Height | M2: Topmark | N2: Topmark colour | O2: Fog signal | P2: Fog period | Q2: MMSI | R2: AIS type | S2: Racon | T2: Status | U2: Installed | V2: Visual prominence | W2: Remarks
A3: =IF(Source!A3="","",Source!A3&"") -> XX-001 | B3: =TRIM(Source!C3&" "&Source!B3&" "&Source!D3) -> Safe water buoy | C3: =IF(Source!E3="","",Source!E3) -> Alfa Approach | D3: =IF(Source!F3="","",ROUND(IF(UPPER(Source!I3)="S",-1,1)*(N(Source!F3)+N(Source!G3)/60+N(Source!H3)/3600),7)) -> 15.5 | E3: =IF(Source!J3="","",ROUND(IF(UPPER(Source!M3)="W",-1,1)*(N(Source!J3)+N(Source!K3)/60+N(Source!L3)/3600),7)) -> 88.2 | F3: =SUBSTITUTE(TRIM(Source!N3&" "&Source!O3&" "&Source!P3)," ","/") -> red/white | G3: =IF(Source!Q3="","",Source!Q3) -> vertical stripes | H3: =IF(Source!R3="","",Source!R3) -> pillar | I3: =IF(Source!S3<>"",Source!S3,IF(Source!C3<>"",Source!C3,"")) | J3: =TRIM(Source!T3&" "&Source!U3&" "&IF(Source!V3="","",Source!V3&"s")&" "&IF(Source!W3="","",Source!W3&"M")) -> LFl W 10s 8M | K3: =IF(Source!X3="","",Source!X3) | L3: =IF(Source!Y3="","",Source!Y3) -> 4 | M3: =IF(Source!Z3="","",Source!Z3) -> sphere | N3: =IF(Source!AA3="","",Source!AA3) -> red | O3: =IF(Source!AB3="","",Source!AB3) | P3: =IF(Source!AC3="","",Source!AC3) | Q3: =IF(Source!AD3="","",TEXT(Source!AD3,"000000000")) | R3: =IF(Source!AE3="","","physical AIS type "&Source!AE3) | S3: =IF(Source!AF3="","",IF(LEN(Source!AF3)=1,UPPER(Source!AF3),"yes")) | T3: =IF(Source!AG3="","",Source!AG3) -> permanent | U3: =IF(Source!AH3="","",YEAR(Source!AH3)&"-"&TEXT(MONTH(Source!AH3),"00")&"-"&TEXT(DAY(Source!AH3),"00")) -> 2019-03-15 | V3: =IF(Source!AI3="","",IF(OR(UPPER(Source!AI3)="YES",UPPER(Source!AI3)="Y"),"visually conspicuous",IF(OR(UPPER(Source!AI3)="NO",UPPER(Source!AI3)="N"),"not visually conspicuous",Source!AI3))) | W3: =IF(Source!AJ3="","",Source!AJ3) -> Fairway buoy
A4: =IF(Source!A4="","",Source!A4&"") -> XX-002 | B4: =TRIM(Source!C4&" "&Source!B4&" "&Source!D4) -> port Lateral buoy | C4: =IF(Source!E4="","",Source!E4) -> Bravo Point | D4: =IF(Source!F4="","",ROUND(IF(UPPER(Source!I4)="S",-1,1)*(N(Source!F4)+N(Source!G4)/60+N(Source!H4)/3600),7)) -> 15.517 | E4: =IF(Source!J4="","",ROUND(IF(UPPER(Source!M4)="W",-1,1)*(N(Source!J4)+N(Source!K4)/60+N(Source!L4)/3600),7)) -> 88.217 | F4: =SUBSTITUTE(TRIM(Source!N4&" "&Source!O4&" "&Source!P4)," ","/") -> red | G4: =IF(Source!Q4="","",Source!Q4) | H4: =IF(Source!R4="","",Source!R4) -> can | I4: =IF(Source!S4<>"",Source!S4,IF(Source!C4<>"",Source!C4,"")) -> port | J4: =TRIM(Source!T4&" "&Source!U4&" "&IF(Source!V4="","",Source!V4&"s")&" "&IF(Source!W4="","",Source!W4&"M")) -> Fl R 4s 5M | K4: =IF(Source!X4="","",Source!X4) | L4: =IF(Source!Y4="","",Source!Y4) | M4: =IF(Source!Z4="","",Source!Z4) -> cylinder | N4: =IF(Source!AA4="","",Source!AA4) -> red | O4: =IF(Source!AB4="","",Source!AB4) | P4: =IF(Source!AC4="","",Source!AC4) | Q4: =IF(Source!AD4="","",TEXT(Source!AD4,"000000000")) | R4: =IF(Source!AE4="","","physical AIS type "&Source!AE4) | S4: =IF(Source!AF4="","",IF(LEN(Source!AF4)=1,UPPER(Source!AF4),"yes")) | T4: =IF(Source!AG4="","",Source!AG4) -> permanent | U4: =IF(Source!AH4="","",YEAR(Source!AH4)&"-"&TEXT(MONTH(Source!AH4),"00")&"-"&TEXT(DAY(Source!AH4),"00")) -> 2020-06-01 | V4: =IF(Source!AI4="","",IF(OR(UPPER(Source!AI4)="YES",UPPER(Source!AI4)="Y"),"visually conspicuous",IF(OR(UPPER(Source!AI4)="NO",UPPER(Source!AI4)="N"),"not visually conspicuous",Source!AI4))) | W4: =IF(Source!AJ4="","",Source!AJ4)
A5: =IF(Source!A5="","",Source!A5&"") -> XX-003 | B5: =TRIM(Source!C5&" "&Source!B5&" "&Source!D5) -> starboard Lateral buoy | C5: =IF(Source!E5="","",Source!E5) -> Charlie Shoal | D5: =IF(Source!F5="","",ROUND(IF(UPPER(Source!I5)="S",-1,1)*(N(Source!F5)+N(Source!G5)/60+N(Source!H5)/3600),7)) -> 15.533333 | E5: =IF(Source!J5="","",ROUND(IF(UPPER(Source!M5)="W",-1,1)*(N(Source!J5)+N(Source!K5)/60+N(Source!L5)/3600),7)) -> 88.233333 | F5: =SUBSTITUTE(TRIM(Source!N5&" "&Source!O5&" "&Source!P5)," ","/") -> green | G5: =IF(Source!Q5="","",Source!Q5) | H5: =IF(Source!R5="","",Source!R5) -> conical | I5: =IF(Source!S5<>"",Source!S5,IF(Source!C5<>"",Source!C5,"")) -> starboard | J5: =TRIM(Source!T5&" "&Source!U5&" "&IF(Source!V5="","",Source!V5&"s")&" "&IF(Source!W5="","",Source!W5&"M")) -> Fl G 4s 5M | K5: =IF(Source!X5="","",Source!X5) | L5: =IF(Source!Y5="","",Source!Y5) | M5: =IF(Source!Z5="","",Source!Z5) -> cone (point up) | N5: =IF(Source!AA5="","",Source!AA5) -> green | O5: =IF(Source!AB5="","",Source!AB5) | P5: =IF(Source!AC5="","",Source!AC5) | Q5: =IF(Source!AD5="","",TEXT(Source!AD5,"000000000")) | R5: =IF(Source!AE5="","","physical AIS type "&Source!AE5) | S5: =IF(Source!AF5="","",IF(LEN(Source!AF5)=1,UPPER(Source!AF5),"yes")) | T5: =IF(Source!AG5="","",Source!AG5) -> permanent | U5: =IF(Source!AH5="","",YEAR(Source!AH5)&"-"&TEXT(MONTH(Source!AH5),"00")&"-"&TEXT(DAY(Source!AH5),"00")) -> 2020-06-01 | V5: =IF(Source!AI5="","",IF(OR(UPPER(Source!AI5)="YES",UPPER(Source!AI5)="Y"),"visually conspicuous",IF(OR(UPPER(Source!AI5)="NO",UPPER(Source!AI5)="N"),"not visually conspicuous",Source!AI5))) | W5: =IF(Source!AJ5="","",Source!AJ5) -> Marks the shoal
A6: =IF(Source!A6="","",Source!A6&"") -> XX-004 | B6: =TRIM(Source!C6&" "&Source!B6&" "&Source!D6) -> N Cardinal buoy | C6: =IF(Source!E6="","",Source!E6) -> Delta North | D6: =IF(Source!F6="","",ROUND(IF(UPPER(Source!I6)="S",-1,1)*(N(Source!F6)+N(Source!G6)/60+N(Source!H6)/3600),7)) -> 15.55 | E6: =IF(Source!J6="","",ROUND(IF(UPPER(Source!M6)="W",-1,1)*(N(Source!J6)+N(Source!K6)/60+N(Source!L6)/3600),7)) -> 88.25 | F6: =SUBSTITUTE(TRIM(Source!N6&" "&Source!O6&" "&Source!P6)," ","/") -> black/yellow | G6: =IF(Source!Q6="","",Source!Q6) -> horizontal stripes | H6: =IF(Source!R6="","",Source!R6) -> pillar | I6: =IF(Source!S6<>"",Source!S6,IF(Source!C6<>"",Source!C6,"")) -> N | J6: =TRIM(Source!T6&" "&Source!U6&" "&IF(Source!V6="","",Source!V6&"s")&" "&IF(Source!W6="","",Source!W6&"M")) -> VQ W 6M | K6: =IF(Source!X6="","",Source!X6) | L6: =IF(Source!Y6="","",Source!Y6) | M6: =IF(Source!Z6="","",Source!Z6) -> 2 cones (points upward) | N6: =IF(Source!AA6="","",Source!AA6) -> black | O6: =IF(Source!AB6="","",Source!AB6) | P6: =IF(Source!AC6="","",Source!AC6) | Q6: =IF(Source!AD6="","",TEXT(Source!AD6,"000000000")) | R6: =IF(Source!AE6="","","physical AIS type "&Source!AE6) | S6: =IF(Source!AF6="","",IF(LEN(Source!AF6)=1,UPPER(Source!AF6),"yes")) | T6: =IF(Source!AG6="","",Source!AG6) -> permanent | U6: =IF(Source!AH6="","",YEAR(Source!AH6)&"-"&TEXT(MONTH(Source!AH6),"00")&"-"&TEXT(DAY(Source!AH6),"00")) -> 2018-11-20 | V6: =IF(Source!AI6="","",IF(OR(UPPER(Source!AI6)="YES",UPPER(Source!AI6)="Y"),"visually conspicuous",IF(OR(UPPER(Source!AI6)="NO",UPPER(Source!AI6)="N"),"not visually conspicuous",Source!AI6))) | W6: =IF(Source!AJ6="","",Source!AJ6)
A7: =IF(Source!A7="","",Source!A7&"") -> XX-005 | B7: =TRIM(Source!C7&" "&Source!B7&" "&Source!D7) -> Lighthouse | C7: =IF(Source!E7="","",Source!E7) -> Echo Tower | D7: =IF(Source!F7="","",ROUND(IF(UPPER(Source!I7)="S",-1,1)*(N(Source!F7)+N(Source!G7)/60+N(Source!H7)/3600),7)) -> 15.583333 | E7: =IF(Source!J7="","",ROUND(IF(UPPER(Source!M7)="W",-1,1)*(N(Source!J7)+N(Source!K7)/60+N(Source!L7)/3600),7)) -> 88.283333 | F7: =SUBSTITUTE(TRIM(Source!N7&" "&Source!O7&" "&Source!P7)," ","/") -> white | G7: =IF(Source!Q7="","",Source!Q7) | H7: =IF(Source!R7="","",Source!R7) | I7: =IF(Source!S7<>"",Source!S7,IF(Source!C7<>"",Source!C7,"")) | J7: =TRIM(Source!T7&" "&Source!U7&" "&IF(Source!V7="","",Source!V7&"s")&" "&IF(Source!W7="","",Source!W7&"M")) -> Fl(2) W 10s 15M | K7: =IF(Source!X7="","",Source!X7) -> 14 | L7: =IF(Source!Y7="","",Source!Y7) -> 18 | M7: =IF(Source!Z7="","",Source!Z7) | N7: =IF(Source!AA7="","",Source!AA7) | O7: =IF(Source!AB7="","",Source!AB7) -> horn | P7: =IF(Source!AC7="","",Source!AC7) -> 30 | Q7: =IF(Source!AD7="","",TEXT(Source!AD7,"000000000")) | R7: =IF(Source!AE7="","","physical AIS type "&Source!AE7) | S7: =IF(Source!AF7="","",IF(LEN(Source!AF7)=1,UPPER(Source!AF7),"yes")) -> K | T7: =IF(Source!AG7="","",Source!AG7) -> permanent | U7: =IF(Source!AH7="","",YEAR(Source!AH7)&"-"&TEXT(MONTH(Source!AH7),"00")&"-"&TEXT(DAY(Source!AH7),"00")) -> 1925-05-01 | V7: =IF(Source!AI7="","",IF(OR(UPPER(Source!AI7)="YES",UPPER(Source!AI7)="Y"),"visually conspicuous",IF(OR(UPPER(Source!AI7)="NO",UPPER(Source!AI7)="N"),"not visually conspicuous",Source!AI7))) -> visually conspicuous | W7: =IF(Source!AJ7="","",Source!AJ7) -> Racon K
A8: =IF(Source!A8="","",Source!A8&"") -> XX-006 | B8: =TRIM(Source!C8&" "&Source!B8&" "&Source!D8) -> Special buoy | C8: =IF(Source!E8="","",Source!E8) -> Foxtrot Works | D8: =IF(Source!F8="","",ROUND(IF(UPPER(Source!I8)="S",-1,1)*(N(Source!F8)+N(Source!G8)/60+N(Source!H8)/3600),7)) -> 15.6 | E8: =IF(Source!J8="","",ROUND(IF(UPPER(Source!M8)="W",-1,1)*(N(Source!J8)+N(Source!K8)/60+N(Source!L8)/3600),7)) -> 88.3 | F8: =SUBSTITUTE(TRIM(Source!N8&" "&Source!O8&" "&Source!P8)," ","/") -> yellow | G8: =IF(Source!Q8="","",Source!Q8) | H8: =IF(Source!R8="","",Source!R8) -> spar | I8: =IF(Source!S8<>"",Source!S8,IF(Source!C8<>"",Source!C8,"")) -> spoil ground mark | J8: =TRIM(Source!T8&" "&Source!U8&" "&IF(Source!V8="","",Source!V8&"s")&" "&IF(Source!W8="","",Source!W8&"M")) -> Fl Y 5s 4M | K8: =IF(Source!X8="","",Source!X8) | L8: =IF(Source!Y8="","",Source!Y8) | M8: =IF(Source!Z8="","",Source!Z8) -> x-shaped | N8: =IF(Source!AA8="","",Source!AA8) -> yellow | O8: =IF(Source!AB8="","",Source!AB8) | P8: =IF(Source!AC8="","",Source!AC8) | Q8: =IF(Source!AD8="","",TEXT(Source!AD8,"000000000")) -> 992001234 | R8: =IF(Source!AE8="","","physical AIS type "&Source!AE8) -> physical AIS type 1 | S8: =IF(Source!AF8="","",IF(LEN(Source!AF8)=1,UPPER(Source!AF8),"yes")) | T8: =IF(Source!AG8="","",Source!AG8) -> permanent | U8: =IF(Source!AH8="","",YEAR(Source!AH8)&"-"&TEXT(MONTH(Source!AH8),"00")&"-"&TEXT(DAY(Source!AH8),"00")) -> 2021-01-10 | V8: =IF(Source!AI8="","",IF(OR(UPPER(Source!AI8)="YES",UPPER(Source!AI8)="Y"),"visually conspicuous",IF(OR(UPPER(Source!AI8)="NO",UPPER(Source!AI8)="N"),"not visually conspicuous",Source!AI8))) | W8: =IF(Source!AJ8="","",Source!AJ8) -> Spoil ground
A9: =IF(Source!A9="","",Source!A9&"") -> XX-007 | B9: =TRIM(Source!C9&" "&Source!B9&" "&Source!D9) -> starboard Lateral beacon | C9: =IF(Source!E9="","",Source!E9) -> Golf Pile | D9: =IF(Source!F9="","",ROUND(IF(UPPER(Source!I9)="S",-1,1)*(N(Source!F9)+N(Source!G9)/60+N(Source!H9)/3600),7)) -> 15.616667 | E9: =IF(Source!J9="","",ROUND(IF(UPPER(Source!M9)="W",-1,1)*(N(Source!J9)+N(Source!K9)/60+N(Source!L9)/3600),7)) -> 88.316667 | F9: =SUBSTITUTE(TRIM(Source!N9&" "&Source!O9&" "&Source!P9)," ","/") -> green | G9: =IF(Source!Q9="","",Source!Q9) | H9: =IF(Source!R9="","",Source!R9) -> pile | I9: =IF(Source!S9<>"",Source!S9,IF(Source!C9<>"",Source!C9,"")) -> starboard | J9: =TRIM(Source!T9&" "&Source!U9&" "&IF(Source!V9="","",Source!V9&"s")&" "&IF(Source!W9="","",Source!W9&"M")) -> Fl G 3s 4M | K9: =IF(Source!X9="","",Source!X9) | L9: =IF(Source!Y9="","",Source!Y9) -> 8 | M9: =IF(Source!Z9="","",Source!Z9) -> cone (point up) | N9: =IF(Source!AA9="","",Source!AA9) -> green | O9: =IF(Source!AB9="","",Source!AB9) | P9: =IF(Source!AC9="","",Source!AC9) | Q9: =IF(Source!AD9="","",TEXT(Source!AD9,"000000000")) | R9: =IF(Source!AE9="","","physical AIS type "&Source!AE9) | S9: =IF(Source!AF9="","",IF(LEN(Source!AF9)=1,UPPER(Source!AF9),"yes")) | T9: =IF(Source!AG9="","",Source!AG9) -> permanent | U9: =IF(Source!AH9="","",YEAR(Source!AH9)&"-"&TEXT(MONTH(Source!AH9),"00")&"-"&TEXT(DAY(Source!AH9),"00")) -> 2019-12-01 | V9: =IF(Source!AI9="","",IF(OR(UPPER(Source!AI9)="YES",UPPER(Source!AI9)="Y"),"visually conspicuous",IF(OR(UPPER(Source!AI9)="NO",UPPER(Source!AI9)="N"),"not visually conspicuous",Source!AI9))) | W9: =IF(Source!AJ9="","",Source!AJ9)
A10: =IF(Source!A10="","",Source!A10&"") | B10: =TRIM(Source!C10&" "&Source!B10&" "&Source!D10) | C10: =IF(Source!E10="","",Source!E10) | D10: =IF(Source!F10="","",ROUND(IF(UPPER(Source!I10)="S",-1,1)*(N(Source!F10)+N(Source!G10)/60+N(Source!H10)/3600),7)) | E10: =IF(Source!J10="","",ROUND(IF(UPPER(Source!M10)="W",-1,1)*(N(Source!J10)+N(Source!K10)/60+N(Source!L10)/3600),7)) | F10: =SUBSTITUTE(TRIM(Source!N10&" "&Source!O10&" "&Source!P10)," ","/") | G10: =IF(Source!Q10="","",Source!Q10) | H10: =IF(Source!R10="","",Source!R10) | I10: =IF(Source!S10<>"",Source!S10,IF(Source!C10<>"",Source!C10,"")) | J10: =TRIM(Source!T10&" "&Source!U10&" "&IF(Source!V10="","",Source!V10&"s")&" "&IF(Source!W10="","",Source!W10&"M")) | K10: =IF(Source!X10="","",Source!X10) | L10: =IF(Source!Y10="","",Source!Y10) | M10: =IF(Source!Z10="","",Source!Z10) | N10: =IF(Source!AA10="","",Source!AA10) | O10: =IF(Source!AB10="","",Source!AB10) | P10: =IF(Source!AC10="","",Source!AC10) | Q10: =IF(Source!AD10="","",TEXT(Source!AD10,"000000000")) | R10: =IF(Source!AE10="","","physical AIS type "&Source!AE10) | S10: =IF(Source!AF10="","",IF(LEN(Source!AF10)=1,UPPER(Source!AF10),"yes")) | T10: =IF(Source!AG10="","",Source!AG10) | U10: =IF(Source!AH10="","",YEAR(Source!AH10)&"-"&TEXT(MONTH(Source!AH10),"00")&"-"&TEXT(DAY(Source!AH10),"00")) | V10: =IF(Source!AI10="","",IF(OR(UPPER(Source!AI10)="YES",UPPER(Source!AI10)="Y"),"visually conspicuous",IF(OR(UPPER(Source!AI10)="NO",UPPER(Source!AI10)="N"),"not visually conspicuous",Source!AI10))) | W10: =IF(Source!AJ10="","",Source!AJ10)
A11: =IF(Source!A11="","",Source!A11&"") | B11: =TRIM(Source!C11&" "&Source!B11&" "&Source!D11) | C11: =IF(Source!E11="","",Source!E11) | D11: =IF(Source!F11="","",ROUND(IF(UPPER(Source!I11)="S",-1,1)*(N(Source!F11)+N(Source!G11)/60+N(Source!H11)/3600),7)) | E11: =IF(Source!J11="","",ROUND(IF(UPPER(Source!M11)="W",-1,1)*(N(Source!J11)+N(Source!K11)/60+N(Source!L11)/3600),7)) | F11: =SUBSTITUTE(TRIM(Source!N11&" "&Source!O11&" "&Source!P11)," ","/") | G11: =IF(Source!Q11="","",Source!Q11) | H11: =IF(Source!R11="","",Source!R11) | I11: =IF(Source!S11<>"",Source!S11,IF(Source!C11<>"",Source!C11,"")) | J11: =TRIM(Source!T11&" "&Source!U11&" "&IF(Source!V11="","",Source!V11&"s")&" "&IF(Source!W11="","",Source!W11&"M")) | K11: =IF(Source!X11="","",Source!X11) | L11: =IF(Source!Y11="","",Source!Y11) | M11: =IF(Source!Z11="","",Source!Z11) | N11: =IF(Source!AA11="","",Source!AA11) | O11: =IF(Source!AB11="","",Source!AB11) | P11: =IF(Source!AC11="","",Source!AC11) | Q11: =IF(Source!AD11="","",TEXT(Source!AD11,"000000000")) | R11: =IF(Source!AE11="","","physical AIS type "&Source!AE11) | S11: =IF(Source!AF11="","",IF(LEN(Source!AF11)=1,UPPER(Source!AF11),"yes")) | T11: =IF(Source!AG11="","",Source!AG11) | U11: =IF(Source!AH11="","",YEAR(Source!AH11)&"-"&TEXT(MONTH(Source!AH11),"00")&"-"&TEXT(DAY(Source!AH11),"00")) | V11: =IF(Source!AI11="","",IF(OR(UPPER(Source!AI11)="YES",UPPER(Source!AI11)="Y"),"visually conspicuous",IF(OR(UPPER(Source!AI11)="NO",UPPER(Source!AI11)="N"),"not visually conspicuous",Source!AI11))) | W11: =IF(Source!AJ11="","",Source!AJ11)
A12: =IF(Source!A12="","",Source!A12&"") | B12: =TRIM(Source!C12&" "&Source!B12&" "&Source!D12) | C12: =IF(Source!E12="","",Source!E12) | D12: =IF(Source!F12="","",ROUND(IF(UPPER(Source!I12)="S",-1,1)*(N(Source!F12)+N(Source!G12)/60+N(Source!H12)/3600),7)) | E12: =IF(Source!J12="","",ROUND(IF(UPPER(Source!M12)="W",-1,1)*(N(Source!J12)+N(Source!K12)/60+N(Source!L12)/3600),7)) | F12: =SUBSTITUTE(TRIM(Source!N12&" "&Source!O12&" "&Source!P12)," ","/") | G12: =IF(Source!Q12="","",Source!Q12) | H12: =IF(Source!R12="","",Source!R12) | I12: =IF(Source!S12<>"",Source!S12,IF(Source!C12<>"",Source!C12,"")) | J12: =TRIM(Source!T12&" "&Source!U12&" "&IF(Source!V12="","",Source!V12&"s")&" "&IF(Source!W12="","",Source!W12&"M")) | K12: =IF(Source!X12="","",Source!X12) | L12: =IF(Source!Y12="","",Source!Y12) | M12: =IF(Source!Z12="","",Source!Z12) | N12: =IF(Source!AA12="","",Source!AA12) | O12: =IF(Source!AB12="","",Source!AB12) | P12: =IF(Source!AC12="","",Source!AC12) | Q12: =IF(Source!AD12="","",TEXT(Source!AD12,"000000000")) | R12: =IF(Source!AE12="","","physical AIS type "&Source!AE12) | S12: =IF(Source!AF12="","",IF(LEN(Source!AF12)=1,UPPER(Source!AF12),"yes")) | T12: =IF(Source!AG12="","",Source!AG12) | U12: =IF(Source!AH12="","",YEAR(Source!AH12)&"-"&TEXT(MONTH(Source!AH12),"00")&"-"&TEXT(DAY(Source!AH12),"00")) | V12: =IF(Source!AI12="","",IF(OR(UPPER(Source!AI12)="YES",UPPER(Source!AI12)="Y"),"visually conspicuous",IF(OR(UPPER(Source!AI12)="NO",UPPER(Source!AI12)="N"),"not visually conspicuous",Source!AI12))) | W12: =IF(Source!AJ12="","",Source!AJ12)
A13: =IF(Source!A13="","",Source!A13&"") | B13: =TRIM(Source!C13&" "&Source!B13&" "&Source!D13) | C13: =IF(Source!E13="","",Source!E13) | D13: =IF(Source!F13="","",ROUND(IF(UPPER(Source!I13)="S",-1,1)*(N(Source!F13)+N(Source!G13)/60+N(Source!H13)/3600),7)) | E13: =IF(Source!J13="","",ROUND(IF(UPPER(Source!M13)="W",-1,1)*(N(Source!J13)+N(Source!K13)/60+N(Source!L13)/3600),7)) | F13: =SUBSTITUTE(TRIM(Source!N13&" "&Source!O13&" "&Source!P13)," ","/") | G13: =IF(Source!Q13="","",Source!Q13) | H13: =IF(Source!R13="","",Source!R13) | I13: =IF(Source!S13<>"",Source!S13,IF(Source!C13<>"",Source!C13,"")) | J13: =TRIM(Source!T13&" "&Source!U13&" "&IF(Source!V13="","",Source!V13&"s")&" "&IF(Source!W13="","",Source!W13&"M")) | K13: =IF(Source!X13="","",Source!X13) | L13: =IF(Source!Y13="","",Source!Y13) | M13: =IF(Source!Z13="","",Source!Z13) | N13: =IF(Source!AA13="","",Source!AA13) | O13: =IF(Source!AB13="","",Source!AB13) | P13: =IF(Source!AC13="","",Source!AC13) | Q13: =IF(Source!AD13="","",TEXT(Source!AD13,"000000000")) | R13: =IF(Source!AE13="","","physical AIS type "&Source!AE13) | S13: =IF(Source!AF13="","",IF(LEN(Source!AF13)=1,UPPER(Source!AF13),"yes")) | T13: =IF(Source!AG13="","",Source!AG13) | U13: =IF(Source!AH13="","",YEAR(Source!AH13)&"-"&TEXT(MONTH(Source!AH13),"00")&"-"&TEXT(DAY(Source!AH13),"00")) | V13: =IF(Source!AI13="","",IF(OR(UPPER(Source!AI13)="YES",UPPER(Source!AI13)="Y"),"visually conspicuous",IF(OR(UPPER(Source!AI13)="NO",UPPER(Source!AI13)="N"),"not visually conspicuous",Source!AI13))) | W13: =IF(Source!AJ13="","",Source!AJ13)
A14: =IF(Source!A14="","",Source!A14&"") | B14: =TRIM(Source!C14&" "&Source!B14&" "&Source!D14) | C14: =IF(Source!E14="","",Source!E14) | D14: =IF(Source!F14="","",ROUND(IF(UPPER(Source!I14)="S",-1,1)*(N(Source!F14)+N(Source!G14)/60+N(Source!H14)/3600),7)) | E14: =IF(Source!J14="","",ROUND(IF(UPPER(Source!M14)="W",-1,1)*(N(Source!J14)+N(Source!K14)/60+N(Source!L14)/3600),7)) | F14: =SUBSTITUTE(TRIM(Source!N14&" "&Source!O14&" "&Source!P14)," ","/") | G14: =IF(Source!Q14="","",Source!Q14) | H14: =IF(Source!R14="","",Source!R14) | I14: =IF(Source!S14<>"",Source!S14,IF(Source!C14<>"",Source!C14,"")) | J14: =TRIM(Source!T14&" "&Source!U14&" "&IF(Source!V14="","",Source!V14&"s")&" "&IF(Source!W14="","",Source!W14&"M")) | K14: =IF(Source!X14="","",Source!X14) | L14: =IF(Source!Y14="","",Source!Y14) | M14: =IF(Source!Z14="","",Source!Z14) | N14: =IF(Source!AA14="","",Source!AA14) | O14: =IF(Source!AB14="","",Source!AB14) | P14: =IF(Source!AC14="","",Source!AC14) | Q14: =IF(Source!AD14="","",TEXT(Source!AD14,"000000000")) | R14: =IF(Source!AE14="","","physical AIS type "&Source!AE14) | S14: =IF(Source!AF14="","",IF(LEN(Source!AF14)=1,UPPER(Source!AF14),"yes")) | T14: =IF(Source!AG14="","",Source!AG14) | U14: =IF(Source!AH14="","",YEAR(Source!AH14)&"-"&TEXT(MONTH(Source!AH14),"00")&"-"&TEXT(DAY(Source!AH14),"00")) | V14: =IF(Source!AI14="","",IF(OR(UPPER(Source!AI14)="YES",UPPER(Source!AI14)="Y"),"visually conspicuous",IF(OR(UPPER(Source!AI14)="NO",UPPER(Source!AI14)="N"),"not visually conspicuous",Source!AI14))) | W14: =IF(Source!AJ14="","",Source!AJ14)
... A202: =IF(Source!A202="","",Source!A202&"") | B202: =TRIM(Source!C202&" "&Source!B202&" "&Source!D202) | C202: =IF(Source!E202="","",Source!E202) | D202: =IF(Source!F202="","",ROUND(IF(UPPER(Source!I202)="S",-1,1)*(N(Source!F202)+N(Source!G202)/60+N(Source!H202)/3600),7)) | E202: =IF(Source!J202="","",ROUND(IF(UPPER(Source!M202)="W",-1,1)*(N(Source!J202)+N(Source!K202)/60+N(Source!L202)/3600),7)) | F202: =SUBSTITUTE(TRIM(Source!N202&" "&Source!O202&" "&Source!P202)," ","/") | G202: =IF(Source!Q202="","",Source!Q202) | H202: =IF(Source!R202="","",Source!R202) | I202: =IF(Source!S202<>"",Source!S202,IF(Source!C202<>"",Source!C202,"")) | J202: =TRIM(Source!T202&" "&Source!U202&" "&IF(Source!V202="","",Source!V202&"s")&" "&IF(Source!W202="","",Source!W202&"M")) | K202: =IF(Source!X202="","",Source!X202) | L202: =IF(Source!Y202="","",Source!Y202) | M202: =IF(Source!Z202="","",Source!Z202) | N202: =IF(Source!AA202="","",Source!AA202) | O202: =IF(Source!AB202="","",Source!AB202) | P202: =IF(Source!AC202="","",Source!AC202) | Q202: =IF(Source!AD202="","",TEXT(Source!AD202,"000000000")) | R202: =IF(Source!AE202="","","physical AIS type "&Source!AE202) | S202: =IF(Source!AF202="","",IF(LEN(Source!AF202)=1,UPPER(Source!AF202),"yes")) | T202: =IF(Source!AG202="","",Source!AG202) | U202: =IF(Source!AH202="","",YEAR(Source!AH202)&"-"&TEXT(MONTH(Source!AH202),"00")&"-"&TEXT(DAY(Source!AH202),"00")) | V202: =IF(Source!AI202="","",IF(OR(UPPER(Source!AI202)="YES",UPPER(Source!AI202)="Y"),"visually conspicuous",IF(OR(UPPER(Source!AI202)="NO",UPPER(Source!AI202)="N"),"not visually conspicuous",Source!AI202))) | W202: =IF(Source!AJ202="","",Source!AJ202)

Sheet Source
A1: Source — type one aid per row in the yellow cells (drop-downs offer the accepted words). The first rows are fictional examples: overwrite or delete them. The S-201 list sheet fills itself.
A2: No | B2: Type | C2: Side / direction | D2: Structure | E2: Name | F2: Lat ° | G2: Lat ' | H2: Lat " | I2: N/S | J2: Lon ° | K2: Lon ' | L2: Lon " | M2: E/W | N2: Colour 1 | O2: Colour 2 | P2: Colour 3 | Q2: Colour pattern | R2: Shape | S2: Special-purpose category | T2: Light rhythm | U2: Light colour | V2: Period (s) | W2: Range (NM) | X2: Focal height (m) | Y2: Height (m) | Z2: Topmark | AA2: Topmark colour | AB2: Fog signal | AC2: Fog period (s) | AD2: MMSI | AE2: AIS type | AF2: Racon | AG2: Status | AH2: Installed | AI2: Visually conspicuous | AJ2: Remarks
A3: XX-001 | B3: Safe water | D3: buoy | E3: Alfa Approach | F3: 15 | G3: 30 | I3: N | J3: 88 | K3: 12 | M3: E | N3: red | O3: white | Q3: vertical stripes | R3: pillar | T3: LFl | U3: W | V3: 10 | W3: 8 | Y3: 4 | Z3: sphere | AA3: red | AG3: permanent | AH3: 43539 | AJ3: Fairway buoy
A4: XX-002 | B4: Lateral | C4: port | D4: buoy | E4: Bravo Point | F4: 15 | G4: 31 | H4: 1.2 | I4: N | J4: 88 | K4: 13 | L4: 1.2 | M4: E | N4: red | R4: can | T4: Fl | U4: R | V4: 4 | W4: 5 | Z4: cylinder | AA4: red | AG4: permanent | AH4: 43983
A5: XX-003 | B5: Lateral | C5: starboard | D5: buoy | E5: Charlie Shoal | F5: 15 | G5: 32 | I5: N | J5: 88 | K5: 14 | M5: E | N5: green | R5: conical | T5: Fl | U5: G | V5: 4 | W5: 5 | Z5: cone (point up) | AA5: green | AG5: permanent | AH5: 43983 | AJ5: Marks the shoal
A6: XX-004 | B6: Cardinal | C6: N | D6: buoy | E6: Delta North | F6: 15 | G6: 33 | I6: N | J6: 88 | K6: 15 | M6: E | N6: black | O6: yellow | Q6: horizontal stripes | R6: pillar | T6: VQ | U6: W | W6: 6 | Z6: 2 cones (points upward) | AA6: black | AG6: permanent | AH6: 43424
A7: XX-005 | B7: Lighthouse | E7: Echo Tower | F7: 15 | G7: 35 | I7: N | J7: 88 | K7: 17 | M7: E | N7: white | T7: Fl(2) | U7: W | V7: 10 | W7: 15 | X7: 14 | Y7: 18 | AB7: horn | AC7: 30 | AF7: K | AG7: permanent | AH7: 9253 | AI7: yes | AJ7: Racon K
A8: XX-006 | B8: Special | D8: buoy | E8: Foxtrot Works | F8: 15 | G8: 36 | I8: N | J8: 88 | K8: 18 | M8: E | N8: yellow | R8: spar | S8: spoil ground mark | T8: Fl | U8: Y | V8: 5 | W8: 4 | Z8: x-shaped | AA8: yellow | AD8: 992001234 | AE8: 1 | AG8: permanent | AH8: 44206 | AJ8: Spoil ground
A9: XX-007 | B9: Lateral | C9: starboard | D9: beacon | E9: Golf Pile | F9: 15 | G9: 37 | I9: N | J9: 88 | K9: 19 | M9: E | N9: green | R9: pile | T9: Fl | U9: G | V9: 3 | W9: 4 | Y9: 8 | Z9: cone (point up) | AA9: green | AG9: permanent | AH9: 43800

Sheet Reference
A1: Accepted words — the drop-downs on the Source sheet read these columns (generated from the app's own value lists; a word outside them may be reported as not understood).
A2: Type | B2: Side / direction | C2: Structure | D2: Colour | E2: Colour pattern | F2: Shape | G2: Special-purpose category | H2: Light rhythm | I2: Light colour | J2: Topmark | K2: Fog signal | L2: AIS type | M2: Status | N2: Yes / no | O2: N / S | P2: E / W
A3: Lateral | B3: port | C3: buoy | D3: white | E3: horizontal stripes | F3: conical | G3: firing danger mark | H3: F | I3: W | J3: cone (point up) | K3: explosive | L3: 1 | M3: permanent | N3: yes | O3: N | P3: E
A4: Cardinal | B4: starboard | C4: beacon | D4: black | E4: vertical stripes | F4: can | G4: target mark | H4: Fl | I4: R | J4: cone (point down) | K4: diaphone | L4: 2 | M4: occasional | N4: no | O4: S | P4: W
A5: Safe water | B5: preferred channel to port | D5: red | E5: diagonal stripes | F5: spherical | G5: marker ship mark | H5: Fl(2) | I5: G | J5: sphere | K5: siren | L5: 3 | M5: recommended
A6: Isolated danger | B6: preferred channel to starboard | D6: green | E6: squared | F6: pillar | G6: degaussing range mark | H6: Fl(3) | I6: Y | J6: 2 spheres | K6: nautophone | M6: not in use
A7: Special | B7: N | D7: blue | E7: stripes (direction unknown) | F7: spar | G7: barge mark | H7: Fl(4) | I7: Bu | J7: cylinder | K7: reed | M7: periodic/intermittent
A8: Emergency wreck | B8: E | D8: yellow | E8: border stripe | F8: barrel | G8: cable mark | H8: Fl(5) | I8: Vi | J8: board | K8: tyfon | M8: reserved
A9: Lighthouse | B9: S | D9: grey | E9: single colour | F9: superbuoy | G9: spoil ground mark | H9: Fl(6) | I9: Or | J9: x-shaped | K9: bell | M9: temporary
A10: Light vessel | B10: W | D10: brown | E10: rectangle | F10: ice buoy | G10: outfall mark | H10: Fl(2+1) | I10: Am | J10: upright cross | K10: whistle | M10: private
A11: Light float | D11: amber | E11: triangle | F11: pole | G11: ODAS | H11: LFl | J11: cube (point up) | K11: gong | M11: mandatory
A12: Mooring buoy | D12: violet | F12: withy | G12: recording mark | H12: Q | J12: 2 cones (point to point) | K12: horn | M12: extinguished
A13: Beacon | D13: orange | F13: tower | G13: seaplane anchorage mark | H13: Q(3) | J13: 2 cones (base to base) | M13: illuminated
D14: magenta | F14: lattice | G14: recreation zone mark | H14: Q(6)+LFl | J14: rhombus | M14: historic
D15: pink | F15: pile | G15: private mark | H15: Q(9) | J15: 2 cones (points upward) | M15: public
F16: cairn | G16: mooring mark | H16: VQ | J16: 2 cones (points downward) | M16: synchronized
F17: buoyant beacon | G17: LANBY | H17: VQ(3) | J17: besom (point up) | M17: watched
G18: leading mark | H18: VQ(6)+LFl | J18: besom (point down) | M18: unwatched
G19: measured distance mark | H19: VQ(9) | J19: flag | M19: existence doubtful
G20: notice mark | H20: UQ | J20: sphere over a rhombus | M20: on request
G21: TSS mark | H21: Iso | J21: square | M21: drop away
G22: anchoring prohibited mark | H22: Oc | J22: rectangle (horizontal) | M22: rising
G23: berthing prohibited mark | H23: Oc(2) | J23: rectangle (vertical) | M23: increasing
G24: overtaking prohibited mark | H24: Oc(3) | J24: trapezium (up) | M24: decreasing
G25: two-way traffic prohibited mark | H25: Oc(4) | J25: trapezium (down) | M25: strong
G26: reduced wake mark | H26: Mo | J26: triangle (point up) | M26: good
G27: speed limit mark | H27: Mo(A) | J27: triangle (point down) | M27: moderately
G28: stop mark | H28: Mo(B) | J28: circle | M28: poor
G29: general warning mark | H29: Mo(U) | J29: two upright crosses (one over the other) | M29: buoyed
... G36: overhead power cable mark | H36: Al.Oc | J36: tubular | M36: manual observation
G37: channel edge gradient mark | H37: Al.LFl | M37: unknown status
G38: telephone mark | H38: Al.Gp | M38: confirmed
G39: ferry crossing mark | H39: FFl | M39: candidate
G40: pipeline mark | H40: Q+LFl | M40: under modification
G41: anchorage mark | H41: VQ+LFl | M41: experimental
G42: clearing mark | H42: UQ+LFl | M42: under removal / deletion
G43: control mark | H43: Gp.Oc | M43: removed / deleted
G44: diving mark | H44: Gp.Fl | M44: candidate for modification
G45: refuge beacon | H45: Gp.VQ
G46: foul ground mark
...

Sheet Read me
A1: S-201 AtoN Studio — spreadsheet template for the Excel → S-201 tab
A3: How to use it
A4: 1. On the Source sheet, type one aid per row in the yellow cells. The drop-downs offer the words the converter reads; the first rows are fictional examples — overwrite or delete them.
A5: 2. The S-201 list sheet fills itself by formula. Do not type there; if you need more than 200 rows, copy its last row down.
A6: 3. Save the workbook (Ctrl+S). The converter reads the values Excel stored at the last save.
A7: 4. In S-201 AtoN Studio open Excel → S-201, load this file and keep the sheet "S-201 list" (the column names are recognised and mapped automatically). Check the required-fields checklist, click Convert, read the conversion report, then Load into Builder, Send to Validator or Download .gml.
A9: Column guide (Source sheet)
A10: Source column | B10: Type this | C10: Example | D10: Becomes on the S-201 list
A11: No | B11: The aid's national / list number (text or number; leading zeros are kept when typed as text) | C11: XX-001 | D11: AtoN number
A12: Type + Side / direction + Structure | B12: The mark family, its side (port / starboard / preferred channel …) or cardinal direction (N / E / S / W), and buoy or beacon. Lighthouse, Light vessel, Light float, Mooring buoy and Beacon need no structure word. | C12: Lateral · port · buoy | D12: Aid type — "port Lateral buoy" → Lateral Buoy, port-hand
A13: Name | B13: The aid's name | C13: Bravo Point | D13: Name
A14: Lat ° ' " N/S and Lon ° ' " E/W | B14: Degrees, minutes, seconds and the hemisphere letter. Decimal degrees: put the whole value in the ° column and leave ' and " blank; decimal minutes: put them in the ' column. | C14: 15 · 31 · 1.2 · N | D14: Latitude / Longitude as signed decimal degrees, 7 decimals
A15: Colour 1 / 2 / 3 + Colour pattern | B15: The body colours from the top (horizontal bands) or the left (vertical stripes); the pattern is required when there is more than one colour. | C15: black · yellow · horizontal stripes | D15: Colour "black/yellow" + Colour pattern
A16: Shape | B16: Buoy shape (can, conical, spherical, pillar, spar …) or beacon shape (pole, pile, tower, lattice …) | C16: pillar | D16: Shape
A17: Special-purpose category | B17: Special-purpose marks only: the category name from the list | C17: spoil ground mark | D17: Category (side / direction for the other families)
A18: Light rhythm + Light colour + Period (s) + Range (NM) | B18: Rhythm as in the List of Lights (Fl, Fl(2), LFl, Q, VQ(9), Iso, Oc …), colour letter (W / R / G / Y …), period in seconds, nominal range in nautical miles. No light: leave all four blank. | C18: Fl(2) · W · 10 · 15 | D18: Light character "Fl(2) W 10s 15M"
A19: Focal height (m), Height (m) | B19: Plain numbers in metres — S-201 requires metres. A value you only have in feet must be converted before typing (feet × 0.3048). | C19: 14 · 18 | D19: Focal height 14, Height 18
A20: Topmark + Topmark colour | B20: The topmark shape from the list and its colour | C20: cone (point up) · green | D20: Topmark / Topmark colour
A21: Fog signal + Fog period (s) | B21: The fog signal type from the list and its period in seconds | C21: horn · 30 | D21: Fog signal / Fog period
... A27: Remarks | B27: Free text | C27: Fairway buoy | D27: Remarks → information text
A29: Notes
A30: The formulas use plain Excel 2007 functions only (IF, TRIM, SUBSTITUTE, ROUND, TEXT with digit masks, YEAR / MONTH / DAY, LEN, UPPER), so the workbook works in old Excel versions and in LibreOffice; dates are written year-month-day without a date mask because date masks differ per language.
A31: What the sheet does not give, the converter fills only from IALA R1001 where the convention is single-valued (a lighthouse's landmark category "tower", a cardinal mark's topmark colour …) and says so in the report; a buoy shape, a beacon shape and a light rhythm are never assumed — give them here or as a same-for-all value in the tab.
A32: Fictional examples only: the names, numbers and positions on the Source sheet are made up.
